{"uuid": "d72d9f8f-310f-49f6-90fd-126f8e3fb2f3", "children": ["72a9d8c7-041e-4ab9-af6e-10376ecf1e6f", "692fa746-1d7e-4abb-8a11-231b9bf93e3c", "cb48dab6-e5a2-4c31-ba5d-abcf86a2d9e3", "3b8fd87e-a04e-437a-9666-7e478e2b31e2", "cb164e96-f99d-49ff-93fa-6c3bde7c8985"], "befores": [{"name": "_xunit_setup_class_fixture_Test_multchamet", "status": "broken", "statusDetails": {"message": "selenium.common.exceptions.WebDriverException: Message: An unknown server-side error occurred while processing the command. Original error: Device 832c16a4 was not in the list of connected devices\nStacktrace:\nUnknownError: An unknown server-side error occurred while processing the command. Original error: Device 832c16a4 was not in the list of connected devices\n    at getResponseForW3CError (C:\\Users\\pgk bqt\\AppData\\Local\\Programs\\Appium Server GUI\\resources\\app\\node_modules\\appium\\node_modules\\appium-base-driver\\lib\\protocol\\errors.js:804:9)\n    at asyncHandler (C:\\Users\\pgk bqt\\AppData\\Local\\Programs\\Appium Server GUI\\resources\\app\\node_modules\\appium\\node_modules\\appium-base-driver\\lib\\protocol\\protocol.js:380:37)\n", "trace": "  File \"E:\\pycharm_file\\Chamet_project\\Lib\\site-packages\\pluggy\\_callers.py\", line 39, in _multicall\n    res = hook_impl.function(*args)\n          ^^^^^^^^^^^^^^^^^^^^^^^^^\n  File \"E:\\pycharm_file\\Chamet_project\\Lib\\site-packages\\_pytest\\fixtures.py\", line 1130, in pytest_fixture_setup\n    result = call_fixture_func(fixturefunc, request, kwargs)\n             ^^^^^^^^^^^^^^^^^^^^^^^^^^^^^^^^^^^^^^^^^^^^^^^\n  File \"E:\\pycharm_file\\Chamet_project\\Lib\\site-packages\\_pytest\\fixtures.py\", line 902, in call_fixture_func\n    fixture_result = next(generator)\n                     ^^^^^^^^^^^^^^^\n  File \"E:\\pycharm_file\\Chamet_project\\Lib\\site-packages\\_pytest\\python.py\", line 864, in xunit_setup_class_fixture\n    _call_with_optional_argument(func, self.obj)\n  File \"E:\\pycharm_file\\Chamet_project\\Lib\\site-packages\\_pytest\\python.py\", line 785, in _call_with_optional_argument\n    func(arg)\n  File \"C:\\Users\\pgk bqt\\PycharmProjects\\Chamet_project\\common\\partytencommon\\multparty_star_end.py\", line 17, in setup_class\n    self.audiencedriver=audience_appium_desired()\n                        ^^^^^^^^^^^^^^^^^^^^^^^^^\n  File \"C:\\Users\\pgk bqt\\PycharmProjects\\Chamet_project\\common\\partytencommon\\audience_desired_caps.py\", line 33, in audience_appium_desired\n    driver = webdriver.Remote('http://localhost' + \":\" + str(data['audience_port']) + '/wd/hub', desired_caps2)\n             ^^^^^^^^^^^^^^^^^^^^^^^^^^^^^^^^^^^^^^^^^^^^^^^^^^^^^^^^^^^^^^^^^^^^^^^^^^^^^^^^^^^^^^^^^^^^^^^^^^\n  File \"E:\\pycharm_file\\Chamet_project\\Lib\\site-packages\\appium\\webdriver\\webdriver.py\", line 234, in __init__\n    super().__init__(\n  File \"E:\\pycharm_file\\Chamet_project\\Lib\\site-packages\\selenium\\webdriver\\remote\\webdriver.py\", line 286, in __init__\n    self.start_session(capabilities, browser_profile)\n  File \"E:\\pycharm_file\\Chamet_project\\Lib\\site-packages\\appium\\webdriver\\webdriver.py\", line 324, in start_session\n    response = self.execute(RemoteCommand.NEW_SESSION, w3c_caps)\n               ^^^^^^^^^^^^^^^^^^^^^^^^^^^^^^^^^^^^^^^^^^^^^^^^^\n  File \"E:\\pycharm_file\\Chamet_project\\Lib\\site-packages\\selenium\\webdriver\\remote\\webdriver.py\", line 440, in execute\n    self.error_handler.check_response(response)\n  File \"E:\\pycharm_file\\Chamet_project\\Lib\\site-packages\\selenium\\webdriver\\remote\\errorhandler.py\", line 245, in check_response\n    raise exception_class(message, screen, stacktrace)\n"}, "start": 1689143641553, "stop": 1689143672682}], "start": 1689143641553, "stop": 1689143673290}