{"uuid": "5e0b7bab-8782-429a-a4a0-bb8afa939604", "children": ["e4e6b558-7689-4a41-b2ca-af29f60e49b7", "5f1225f8-99ea-4690-9eba-713237324865", "33f33905-b17f-4d70-9359-d13383661826", "163ff1ec-b9a2-4ab1-8678-28431271616a", "f77a5a8c-9b00-4f05-97c8-908737b92965", "95eee5ed-a1e7-4216-9da4-bbbd73950510", "aa201e4c-2d80-41cf-b5a7-0bb9fcb89a04", "40ac8dfb-6849-4dfe-8a33-6b1d2a518b99", "6b0cb367-c77a-413e-9165-91ab7e8fca18", "3bbc85f5-c01c-4792-99de-574f178633e0", "ae70f0c6-28bf-499f-bcb9-6c093ae9e778", "62b9cdc5-9555-4211-9f4e-f6843355617b", "82187430-089b-447b-9fc6-3ad8ed29fe61", "95231e34-f181-43cc-a5cf-f61bfeb02cfb", "fc66b1c6-9c85-4d64-ac71-77bf40046d79", "17e98da5-1b51-4522-8018-b3eab151a718", "e1f6ffac-ba62-4977-8183-3a8bb17ac091", "2a885c1a-8873-4ef2-86b4-8cd62d2e5caa", "5c739a66-889f-4509-8223-164d0a81c6b2", "9983e7af-b389-467b-ada9-e16c86e8bfb2", "5f54ace4-49c5-49d2-9d90-1acfcd4dd4ea", "39d9c591-d99f-4025-92d4-32643ef30884", "a3c5776b-1a7d-48c6-9715-754471538354", "29fa7be0-4bea-4252-afcd-eb4ab7f87390", "b6203bff-58d2-4ce4-87d0-11f963dd8bff", "c9eb274a-ab79-4fbc-bb69-84026a3c25ca", "450d8623-fd18-47f1-b4b7-8659e46c6184", "36d0670c-f73b-487a-9cf5-f89b265d57bb", "3a521deb-7c8d-4cd9-8754-50fd03aca279", "67b2e6bc-9a64-4d28-987e-206b94f429e2", "1bca33ef-f32d-4d39-adad-491b029f9cbc", "42e9960e-5801-4e82-bc54-c6ce57fed195", "6fed17dd-6cbf-4d66-a753-fbb164180dae", "b0004b8a-16ad-446f-8fa8-429eed65e686"], "befores": [{"name": "_xunit_setup_class_fixture_Test_multchamet", "status": "broken", "statusDetails": {"message": "selenium.common.exceptions.WebDriverException: Message: An unknown server-side error occurred while processing the command. Original error: Device 832c16a4 was not in the list of connected devices\nStacktrace:\nUnknownError: An unknown server-side error occurred while processing the command. Original error: Device 832c16a4 was not in the list of connected devices\n    at getResponseForW3CError (C:\\Users\\pgk bqt\\AppData\\Local\\Programs\\Appium Server GUI\\resources\\app\\node_modules\\appium\\node_modules\\appium-base-driver\\lib\\protocol\\errors.js:804:9)\n    at asyncHandler (C:\\Users\\pgk bqt\\AppData\\Local\\Programs\\Appium Server GUI\\resources\\app\\node_modules\\appium\\node_modules\\appium-base-driver\\lib\\protocol\\protocol.js:380:37)\n", "trace": "  File \"E:\\pycharm_file\\Chamet_project\\Lib\\site-packages\\pluggy\\_callers.py\", line 39, in _multicall\n    res = hook_impl.function(*args)\n          ^^^^^^^^^^^^^^^^^^^^^^^^^\n  File \"E:\\pycharm_file\\Chamet_project\\Lib\\site-packages\\_pytest\\fixtures.py\", line 1130, in pytest_fixture_setup\n    result = call_fixture_func(fixturefunc, request, kwargs)\n             ^^^^^^^^^^^^^^^^^^^^^^^^^^^^^^^^^^^^^^^^^^^^^^^\n  File \"E:\\pycharm_file\\Chamet_project\\Lib\\site-packages\\_pytest\\fixtures.py\", line 902, in call_fixture_func\n    fixture_result = next(generator)\n                     ^^^^^^^^^^^^^^^\n  File \"E:\\pycharm_file\\Chamet_project\\Lib\\site-packages\\_pytest\\python.py\", line 864, in xunit_setup_class_fixture\n    _call_with_optional_argument(func, self.obj)\n  File \"E:\\pycharm_file\\Chamet_project\\Lib\\site-packages\\_pytest\\python.py\", line 785, in _call_with_optional_argument\n    func(arg)\n  File \"C:\\Users\\pgk bqt\\PycharmProjects\\Chamet_project\\common\\partytencommon\\multparty_star_end.py\", line 17, in setup_class\n    self.audiencedriver=audience_appium_desired()\n                        ^^^^^^^^^^^^^^^^^^^^^^^^^\n  File \"C:\\Users\\pgk bqt\\PycharmProjects\\Chamet_project\\common\\partytencommon\\audience_desired_caps.py\", line 33, in audience_appium_desired\n    driver = webdriver.Remote('http://localhost' + \":\" + str(data['audience_port']) + '/wd/hub', desired_caps2)\n             ^^^^^^^^^^^^^^^^^^^^^^^^^^^^^^^^^^^^^^^^^^^^^^^^^^^^^^^^^^^^^^^^^^^^^^^^^^^^^^^^^^^^^^^^^^^^^^^^^^\n  File \"E:\\pycharm_file\\Chamet_project\\Lib\\site-packages\\appium\\webdriver\\webdriver.py\", line 234, in __init__\n    super().__init__(\n  File \"E:\\pycharm_file\\Chamet_project\\Lib\\site-packages\\selenium\\webdriver\\remote\\webdriver.py\", line 286, in __init__\n    self.start_session(capabilities, browser_profile)\n  File \"E:\\pycharm_file\\Chamet_project\\Lib\\site-packages\\appium\\webdriver\\webdriver.py\", line 324, in start_session\n    response = self.execute(RemoteCommand.NEW_SESSION, w3c_caps)\n               ^^^^^^^^^^^^^^^^^^^^^^^^^^^^^^^^^^^^^^^^^^^^^^^^^\n  File \"E:\\pycharm_file\\Chamet_project\\Lib\\site-packages\\selenium\\webdriver\\remote\\webdriver.py\", line 440, in execute\n    self.error_handler.check_response(response)\n  File \"E:\\pycharm_file\\Chamet_project\\Lib\\site-packages\\selenium\\webdriver\\remote\\errorhandler.py\", line 245, in check_response\n    raise exception_class(message, screen, stacktrace)\n"}, "start": 1689055090968, "stop": 1689055123559}], "start": 1689055090968, "stop": 1689055125706}